Workbook

Sheet Ngan_hang_cau_hoi
B1: STT | C1: Câu hỏi | D1: Đáp án A | E1: Đáp án B | F1: Đáp án C | G1: Đáp án D | H1: Đ/A đúng | I1: Đ/A | J1: LV | K1: nội dung | L1: Đ/A đúng
B2: 1 | C2: Tốc độ đọc/ghi dữ liệu giữu ổ cứng SSD và HDD | D2: Tốc độ đọc/ghi dữ liệu của ổ cứng bằng nhau. | E2: Tốc độ đọc/ghi dữ liệu của ổ cứng HDD nhanh hơn. | F2: Tốc độ đọc/ghi dữ liệu của ổ cứng SSD nhanh hơn. | G2: Tốc độ đọc/ghi dữ liệu của ổ cứng SSD chậm hơn. | H2: C | I2: =IF(H2="A",D2,IF(H2="B",E2,IF(H2="C",F2,IF(H2="D",G2)))) -> Tốc độ đọc/ghi dữ liệu của ổ cứng SSD nhanh hơn. | J2: Dễ | K2: Chương 1 | L2: C | N2: Dễ | O2: =COUNTIF(J:J,N2) -> 34 | P2: =O2/$Q$2*100% -> 0.28333333 | Q2: =SUM(O2:O4) -> 120
B3: 2 | C3: Thiết bị nào giúp làm mát CPU? | D3: Case | E3: Heatsink/Fan | F3: RAM | G3: SSD | H3: B | I3: =IF(H3="A",D3,IF(H3="B",E3,IF(H3="C",F3,IF(H3="D",G3)))) -> Heatsink/Fan | J3: Dễ | K3: Chương 1 | L3: B | N3: Trung bình | O3: =COUNTIF(J:J,N3) -> 86 | P3: =O3/$Q$2*100% -> 0.71666667
B4: 3 | C4: RAM DDR4 thường có bao nhiêu chân? | D4: 240 | E4: 288 | F4: 184 | G4: 200 | H4: B | I4: =IF(H4="A",D4,IF(H4="B",E4,IF(H4="C",F4,IF(H4="D",G4)))) -> 288 | J4: Dễ | K4: Chương 1 | L4: B
B5: 4 | C5: RAM có chức năng chính là gì? | D5: Lưu trữ tạm thời | E5: Lưu trữ lâu dài | F5: Xuất hình ảnh | G5: Cấp điện | H5: A | I5: =IF(H5="A",D5,IF(H5="B",E5,IF(H5="C",F5,IF(H5="D",G5)))) -> Lưu trữ tạm thời | J5: Dễ | K5: Chương 1 | L5: A | N5: Chương 1 | O5: =COUNTIF(K:K,N5) -> 36 | Q5: =SUM(O5:O8) -> 120
B6: 5 | C6: Ổ SSD SATA thường có kích thước phổ biến nào? | D6: 3.5 inch | E6: 2.5 inch | F6: 5 inch | G6: 1.8 inch | H6: B | I6: =IF(H6="A",D6,IF(H6="B",E6,IF(H6="C",F6,IF(H6="D",G6)))) -> 2.5 inch | J6: Dễ | K6: Chương 1 | L6: B | N6: Chương 2 | O6: =COUNTIF(K:K,N6) -> 11
B7: 6 | C7: Ổ SSD SATA cần nguồn từ: | D7: Cáp PCI-E | E7: Cáp SATA power | F7: Cáp VGA | G7: Cáp USB | H7: B | I7: =IF(H7="A",D7,IF(H7="B",E7,IF(H7="C",F7,IF(H7="D",G7)))) -> Cáp SATA power | J7: Dễ | K7: Chương 1 | L7: B | N7: Chương 3 & 4 | O7: =COUNTIF(K:K,N7) -> 29
A8: đã sửa | B8: 7 | C8: Ổ cứng SSD lưu dữ liệu bằng công nghệ nào? | D8: ổ SSD sử công nghệ lưu trữ từ tính. | E8: ổ SSD sử công nghệ lưu trữ flash. | F8: ổ SSD sử công nghệ lưu trữ đĩa từ và đầu kim đọc dữ liệu | G8: ổ SSD chỉ để đọc dữ liệu. Dữ liệu được ghi vào từ lúc sản xuất. | H8: B | I8: =IF(H8="A",D8,IF(H8="B",E8,IF(H8="C",F8,IF(H8="D",G8)))) -> ổ SSD sử công nghệ lưu trữ flash. | J8: Dễ | K8: Chương 1 | L8: B | N8: Chương 5 | O8: =COUNTIF(K:K,N8) -> 44
A9: đã sửa, thay câu hỏi | B9: 8 | C9: Nguồn máy tính còn gọi là gì? | D9: GPU | E9: PSU | F9: UPS | G9: ROM | H9: B | I9: =IF(H9="A",D9,IF(H9="B",E9,IF(H9="C",F9,IF(H9="D",G9)))) -> PSU | J9: Dễ | K9: Chương 1 | L9: B
B10: 9 | C10: Nếu mainboard hỗ trợ DDR5, RAM DDR4 sẽ: | D10: Chạy chậm | E10: Không lắp được | F10: Chạy bình thường | G10: Chạy nửa tốc độ | H10: B | I10: =IF(H10="A",D10,IF(H10="B",E10,IF(H10="C",F10,IF(H10="D",G10)))) -> Không lắp được | J10: Dễ | K10: Chương 1 | L10: B
B11: 10 | C11: Nếu CPU không đúng socket với mainboard thì: | D11: Lắp được nhưng máy chạy chậm. | E11: Không lắp được CPU. | F11: Không nhận RAM. | G11: Không có vấn đề gì. | H11: B | I11: =IF(H11="A",D11,IF(H11="B",E11,IF(H11="C",F11,IF(H11="D",G11)))) -> Không lắp được CPU. | J11: Dễ | K11: Chương 1 | L11: B
B12: 11 | C12: Mainboard Micro-ATX có thể lắp vào case ATX không? | D12: Có | E12: Không | F12: Chỉ khi dùng adapter | G12: Chỉ khi nâng cấp BIOS | H12: A | I12: =IF(H12="A",D12,IF(H12="B",E12,IF(H12="C",F12,IF(H12="D",G12)))) -> Có | J12: Dễ | K12: Chương 1 | L12: A
B13: 12 | C13: Mainboard là gì? | D13: Thiết bị lưu trữ | E13: Bo mạch chủ | F13: Thiết bị xuất hình | G13: Thiết bị nhập | H13: B | I13: =IF(H13="A",D13,IF(H13="B",E13,IF(H13="C",F13,IF(H13="D",G13)))) -> Bo mạch chủ | J13: Dễ | K13: Chương 1 | L13: B
B14: 13 | C14: CPU có cache L1, L2, L3. Trong đó cache nhanh nhất là: | D14: L1 | E14: L2 | F14: L3 | G14: Như nhau, chỉ khác về dung lượng | H14: A | I14: =IF(H14="A",D14,IF(H14="B",E14,IF(H14="C",F14,IF(H14="D",G14)))) -> L1 | J14: Dễ | K14: Chương 1 | L14: A
B15: 14 | C15: Thông tin “Intel® Core™ i9-8950HK, 4.80 GHz, 12 MB Intel® Smart Cache” mô tả: | D15: Bộ nhớ cache L1 là 12 MB | E15: Bộ nhớ cache L2 là 12 MB | F15: Bộ nhớ cache L3 là 12 MB | G15: Bộ nhớ cache L1+L2+L3 là 12 MB | H15: C | I15: =IF(H15="A",D15,IF(H15="B",E15,IF(H15="C",F15,IF(H15="D",G15)))) -> Bộ nhớ cache L3 là 12 MB | J15: Trung bình | K15: Chương 1 | L15: C
B16: 15 | C16: Thông tin “Intel® Core™ i9-8950HK, 4.80 GHz, 12 MB Intel® Smart Cache” mô tả: | D16: thế hệ thứ 8 | E16: thế hệ thứ 9 | F16: thế hệ thứ 12 | G16: CPU có 9 nhân | H16: A | I16: =IF(H16="A",D16,IF(H16="B",E16,IF(H16="C",F16,IF(H16="D",G16)))) -> thế hệ thứ 8 | J16: Trung bình | K16: Chương 1 | L16: A
B17: 16 | C17: Thông số Dual Channel RAM giúp: | D17: tăng dung lượng ổ cứng | E17: tăng số nhân CPU | F17: tăng băng thông truy cập bộ nhớ | G17: tăng dung lượng cache | H17: C | I17: =IF(H17="A",D17,IF(H17="B",E17,IF(H17="C",F17,IF(H17="D",G17)))) -> tăng băng thông truy cập bộ nhớ | J17: trung bình | K17: Chương 1 | L17: C
B18: 17 | C18: Sử dụng 2 thanh RAM cùng loại, khác bus nhưng khi lắp đặt vào bo mạch chủ thì: | D18: chạy theo bus thấp hơn | E18: chạy bus cao hơn | F18: không nhận RAM | G18: chạy bus bằng trung bình của 2 RAM | H18: A | I18: =IF(H18="A",D18,IF(H18="B",E18,IF(H18="C",F18,IF(H18="D",G18)))) -> chạy theo bus thấp hơn | J18: Trung bình | K18: Chương 1 | L18: A
B19: 18 | C19: Socket AM4 dùng cho CPU hãng nào? | D19: Intel | E19: AMD | F19: Apple | G19: Qualcomm | H19: B | I19: =IF(H19="A",D19,IF(H19="B",E19,IF(H19="C",F19,IF(H19="D",G19)))) -> AMD | J19: Trung bình | K19: Chương 1 | L19: B
B20: 19 | C20: SATA III có tốc độ tối đa lý thuyết bao nhiêu? | D20: 300 MB/s | E20: 600 MB/s | F20: 1 GB/s | G20: 6 GB/s | H20: B | I20: =IF(H20="A",D20,IF(H20="B",E20,IF(H20="C",F20,IF(H20="D",G20)))) -> 600 MB/s | J20: Trung bình | K20: Chương 1 | L20: B
B21: 20 | C21: RAM bus cao hơn thường mang lại lợi ích gì? | D21: Tăng tốc độ truyền dữ liệu | E21: Giảm dung lượng | F21: Giảm điện áp | G21: Giảm nhiệt | H21: A | I21: =IF(H21="A",D21,IF(H21="B",E21,IF(H21="C",F21,IF(H21="D",G21)))) -> Tăng tốc độ truyền dữ liệu | J21: Trung bình | K21: Chương 1 | L21: A
... B30: 29 | C30: Lắp CPU Intel Gen 12 cần loại socket nào? | D30: LGA1151 | E30: LGA1200 | F30: LGA1700 | G30: AM4 | H30: C | I30: =IF(H30="A",D30,IF(H30="B",E30,IF(H30="C",F30,IF(H30="D",G30)))) -> LGA1700 | J30: Trung bình | K30: Chương 1 | L30: C
A31: đã sửa | B31: 30 | C31: Khi lắp RAM sai khe trên mainboard hỗ trợ dual channel thì điều gì xảy ra? | D31: Không chạy dual channel | E31: Không lên nguồn | F31: Hỏng RAM | G31: Cháy main | H31: A | I31: =IF(H31="A",D31,IF(H31="B",E31,IF(H31="C",F31,IF(H31="D",G31)))) -> Không chạy dual channel | J31: Trung bình | K31: Chương 1 | L31: A
B32: 31 | C32: Khi lắp NVMe cần: | D32: khe M.2 | E32: khe PCI | F32: SATA | G32: RAM slot | H32: A | I32: =IF(H32="A",D32,IF(H32="B",E32,IF(H32="C",F32,IF(H32="D",G32)))) -> khe M.2 | J32: Trung bình | K32: Chương 1 | L32: A
A33: đã sửa | B33: 32 | C33: Hai thanh RAM cùng loại DDR3 nhưng có bus là 1333MHz và 1600MHz thì khi cắm: | D33: Không chạy được | E33: Chạy ở 2666 MHz | F33: Hỏng RAM | G33: Không nhận RAM | H33: B | I33: =IF(H33="A",D33,IF(H33="B",E33,IF(H33="C",F33,IF(H33="D",G33)))) -> Chạy ở 2666 MHz | J33: Trung bình | K33: Chương 1 | L33: B
B34: 33 | C34: GPU rời cần cấp thêm nguồn từ đâu? | D34: PSU qua cáp PCIe | E34: RAM slot | F34: SATA cable | G34: USB port | H34: A | I34: =IF(H34="A",D34,IF(H34="B",E34,IF(H34="C",F34,IF(H34="D",G34)))) -> PSU qua cáp PCIe | J34: Trung bình | K34: Chương 1 | L34: A
B35: 34 | C35: Điều kiện để RAM chạy Dual Channel | D35: Thiết bị phải có ít nhất 2 thanh RAM, cùng loại, cùng bus và có dung lượng giống nhau. | E35: Thiết bị chỉ cần cắm 2 thanh RAM trở lên. | F35: Thiết bị phải có ít nhất 2 thanh RAM, cùng loại, cùng bus và không cần dung lượng giống nhau. | G35: Thiết bị chỉ cần cắm ít nhất 2 thanh RAM cùng bus. | H35: A | I35: =IF(H35="A",D35,IF(H35="B",E35,IF(H35="C",F35,IF(H35="D",G35)))) -> Thiết bị phải có ít nhất 2 thanh RAM, cùng loại, cùng bus và có dung lượng giống nhau. | J35: Trung bình | K35: Chương 1 | L35: A
B36: 35 | C36: Chuẩn giao tiếp của ổ SSD NVMe là gì? | D36: SATA | E36: PCIe | F36: IDE | G36: USB | H36: B | I36: =IF(H36="A",D36,IF(H36="B",E36,IF(H36="C",F36,IF(H36="D",G36)))) -> PCIe | J36: Trung bình | K36: Chương 1 | L36: B
B37: 36 | C37: Card đồ họa rời được cắm vào khe nào trên mainboard? | D37: PCI | E37: PCIe x16 | F37: SATA | G37: M.2 | H37: B | I37: =IF(H37="A",D37,IF(H37="B",E37,IF(H37="C",F37,IF(H37="D",G37)))) -> PCIe x16 | J37: Trung bình | K37: Chương 1 | L37: B
B38: 37 | C38: Thông số Socket CPU dùng để: | D38: xác định loại bo mạch chủ tương thích | E38: xác định loại RAM | F38: xác định dung lượng ổ cứng | G38: xác định card màn hình | H38: A | I38: =IF(H38="A",D38,IF(H38="B",E38,IF(H38="C",F38,IF(H38="D",G38)))) -> xác định loại bo mạch chủ tương thích | J38: Dễ | K38: Chương 2 | L38: A
B39: 38 | C39: Khe PCIe x16 thường dùng để lắp thiết bị nào? | D39: RAM | E39: GPU | F39: SSD | G39: CPU | H39: B | I39: =IF(H39="A",D39,IF(H39="B",E39,IF(H39="C",F39,IF(H39="D",G39)))) -> GPU | J39: Dễ | K39: Chương 2 | L39: B
B40: 39 | C40: CPU được lắp vào đâu trên mainboard? | D40: PCIe slot | E40: RAM slot | F40: CPU socket | G40: SATA port | H40: C | I40: =IF(H40="A",D40,IF(H40="B",E40,IF(H40="C",F40,IF(H40="D",G40)))) -> CPU socket | J40: Dễ | K40: Chương 2 | L40: C
B41: 40 | C41: CPU có Base Clock 2.8 GHz, Turbo Boost 4.0 GHz nghĩa là: | D41: CPU có thể tự động tăng xung lên 4.0 GHz khi cần | E41: CPU luôn chạy 4.0 GHz | F41: CPU không chạy dưới 4 GHz | G41: CPU chỉ chạy 2.8 GHz | H41: A | I41: =IF(H41="A",D41,IF(H41="B",E41,IF(H41="C",F41,IF(H41="D",G41)))) -> CPU có thể tự động tăng xung lên 4.0 GHz khi cần | J41: Dễ | K41: Chương 2 | L41: A
A42: đã sửa, thay câu hỏi | B42: 41 | C42: RAM DDR4 không thể lắp vào khe DDR5 vì lý do chính nào? | D42: Khác dung lượng | E42: Khác vị trí rãnh | F42: Khác hãng | G42: Khác màu | H42: B | I42: =IF(H42="A",D42,IF(H42="B",E42,IF(H42="C",F42,IF(H42="D",G42)))) -> Khác vị trí rãnh | J42: Trung bình | K42: Chương 2 | L42: B
B43: 42 | C43: Nếu PSU công suất quá thấp có thể gây ra hiện tượng gì? | D43: Máy tắt đột ngột | E43: RAM tăng dung lượng | F43: SSD nhanh hơn | G43: GPU mạnh hơn | H43: A | I43: =IF(H43="A",D43,IF(H43="B",E43,IF(H43="C",F43,IF(H43="D",G43)))) -> Máy tắt đột ngột | J43: Trung bình | K43: Chương 2 | L43: A
A44: đã sửa | B44: 43 | C44: Máy bật nhưng không lên hình, nguyên nhân phổ biến nhất khi lắp ráp? | D44: RAM lỏng | E44: Chuột lỗi | F44: Bàn phím lỗi | G44: Loa lỗi | H44: A | I44: =IF(H44="A",D44,IF(H44="B",E44,IF(H44="C",F44,IF(H44="D",G44)))) -> RAM lỏng | J44: Trung bình | K44: Chương 2 | L44: A
B45: 44 | C45: Lắp SSD NVMe vào khe SATA: | D45: Không lắp được | E45: Chạy chậm | F45: Chạy bình thường | G45: Không nhận RAM | H45: A | I45: =IF(H45="A",D45,IF(H45="B",E45,IF(H45="C",F45,IF(H45="D",G45)))) -> Không lắp được | J45: Trung bình | K45: Chương 2 | L45: A
B46: 45 | C46: Lắp SSD NVMe nhưng BIOS không nhận. Nguyên nhân có thể là gì? | D46: Main không hỗ trợ NVMe | E46: RAM lỗi | F46: GPU yếu | G46: Màn hình hỏng | H46: A | I46: =IF(H46="A",D46,IF(H46="B",E46,IF(H46="C",F46,IF(H46="D",G46)))) -> Main không hỗ trợ NVMe | J46: Trung bình | K46: Chương 2 | L46: A
A47: đã sửa, thay câu hỏi | B47: 46 | C47: Khe M.2 trên mainboard thường dùng để lắp linh kiện nào? | D47: RAM | E47: SSD NVMe | F47: GPU | G47: CPU | H47: B | I47: =IF(H47="A",D47,IF(H47="B",E47,IF(H47="C",F47,IF(H47="D",G47)))) -> SSD NVMe | J47: Trung bình | K47: Chương 2 | L47: B
B48: 47 | C48: CPU quá nhiệt thường do nguyên nhân nào? | D48: Thiếu keo tản nhiệt | E48: Thiếu RAM | F48: Ổ cứng chậm | G48: Thiếu chuột | H48: A | I48: =IF(H48="A",D48,IF(H48="B",E48,IF(H48="C",F48,IF(H48="D",G48)))) -> Thiếu keo tản nhiệt | J48: Trung bình | K48: Chương 2 | L48: A
...

Sheet form W
A1: STT | B1: Chương | C1: LV | D1: câu | H1: Đáp án | J1: ĐA | L1: 6
A2: 0 | B2: =VLOOKUP(D2,Ngan_hang_cau_hoi!$B$2:$K$142,10,0) -> Chương 1 | C2: =VLOOKUP(D2,Ngan_hang_cau_hoi!$B$2:$K$142,9,0) -> Dễ | D2: =INT(A2/5)+1 -> 1 | F2: =IF(L2=2,COUNTIF($L$1:L2,2),"") -> 1 | G2: =VLOOKUP(D2,Ngan_hang_cau_hoi!$B$2:$K$142,L2,0) -> Tốc độ đọc/ghi dữ liệu giữu ổ cứng SSD và HDD | H2: =IFERROR(VLOOKUP(J2,Ngan_hang_cau_hoi!$I$2:$L$142,4,0),"") | J2: =IF(VLOOKUP(D2,Ngan_hang_cau_hoi!$B$2:$K$142,8,0)=G2,G2,"") | L2: =IF(L1=6,2,L1+1) -> 2
A3: 1 | B3: =VLOOKUP(D3,Ngan_hang_cau_hoi!$B$2:$K$142,10,0) -> Chương 1 | C3: =VLOOKUP(D3,Ngan_hang_cau_hoi!$B$2:$K$142,9,0) -> Dễ | D3: =INT(A3/5)+1 -> 1 | F3: =IF(L3=2,COUNTIF($L$1:L3,2),"") | G3: =VLOOKUP(D3,Ngan_hang_cau_hoi!$B$2:$K$142,L3,0) -> Tốc độ đọc/ghi dữ liệu của ổ cứng bằng nhau. | H3: =IFERROR(VLOOKUP(J3,Ngan_hang_cau_hoi!$I$2:$L$142,4,0),"") | J3: =IF(VLOOKUP(D3,Ngan_hang_cau_hoi!$B$2:$K$142,8,0)=G3,G3,"") | L3: =IF(L2=6,2,L2+1) -> 3
A4: 2 | B4: =VLOOKUP(D4,Ngan_hang_cau_hoi!$B$2:$K$142,10,0) -> Chương 1 | C4: =VLOOKUP(D4,Ngan_hang_cau_hoi!$B$2:$K$142,9,0) -> Dễ | D4: =INT(A4/5)+1 -> 1 | F4: =IF(L4=2,COUNTIF($L$1:L4,2),"") | G4: =VLOOKUP(D4,Ngan_hang_cau_hoi!$B$2:$K$142,L4,0) -> Tốc độ đọc/ghi dữ liệu của ổ cứng HDD nhanh hơn. | H4: =IFERROR(VLOOKUP(J4,Ngan_hang_cau_hoi!$I$2:$L$142,4,0),"") | J4: =IF(VLOOKUP(D4,Ngan_hang_cau_hoi!$B$2:$K$142,8,0)=G4,G4,"") | L4: =IF(L3=6,2,L3+1) -> 4
A5: 3 | B5: =VLOOKUP(D5,Ngan_hang_cau_hoi!$B$2:$K$142,10,0) -> Chương 1 | C5: =VLOOKUP(D5,Ngan_hang_cau_hoi!$B$2:$K$142,9,0) -> Dễ | D5: =INT(A5/5)+1 -> 1 | F5: =IF(L5=2,COUNTIF($L$1:L5,2),"") | G5: =VLOOKUP(D5,Ngan_hang_cau_hoi!$B$2:$K$142,L5,0) -> Tốc độ đọc/ghi dữ liệu của ổ cứng SSD nhanh hơn. | H5: =IFERROR(VLOOKUP(J5,Ngan_hang_cau_hoi!$I$2:$L$142,4,0),"") -> C | J5: =IF(VLOOKUP(D5,Ngan_hang_cau_hoi!$B$2:$K$142,8,0)=G5,G5,"") -> Tốc độ đọc/ghi dữ liệu của ổ cứng SSD nhanh hơn. | L5: =IF(L4=6,2,L4+1) -> 5
A6: 4 | B6: =VLOOKUP(D6,Ngan_hang_cau_hoi!$B$2:$K$142,10,0) -> Chương 1 | C6: =VLOOKUP(D6,Ngan_hang_cau_hoi!$B$2:$K$142,9,0) -> Dễ | D6: =INT(A6/5)+1 -> 1 | F6: =IF(L6=2,COUNTIF($L$1:L6,2),"") | G6: =VLOOKUP(D6,Ngan_hang_cau_hoi!$B$2:$K$142,L6,0) -> Tốc độ đọc/ghi dữ liệu của ổ cứng SSD chậm hơn. | H6: =IFERROR(VLOOKUP(J6,Ngan_hang_cau_hoi!$I$2:$L$142,4,0),"") | J6: =IF(VLOOKUP(D6,Ngan_hang_cau_hoi!$B$2:$K$142,8,0)=G6,G6,"") | L6: =IF(L5=6,2,L5+1) -> 6
A7: 5 | B7: =VLOOKUP(D7,Ngan_hang_cau_hoi!$B$2:$K$142,10,0) -> Chương 1 | C7: =VLOOKUP(D7,Ngan_hang_cau_hoi!$B$2:$K$142,9,0) -> Dễ | D7: =INT(A7/5)+1 -> 2 | F7: =IF(L7=2,COUNTIF($L$1:L7,2),"") -> 2 | G7: =VLOOKUP(D7,Ngan_hang_cau_hoi!$B$2:$K$142,L7,0) -> Thiết bị nào giúp làm mát CPU? | H7: =IFERROR(VLOOKUP(J7,Ngan_hang_cau_hoi!$I$2:$L$142,4,0),"") | J7: =IF(VLOOKUP(D7,Ngan_hang_cau_hoi!$B$2:$K$142,8,0)=G7,G7,"") | L7: =IF(L6=6,2,L6+1) -> 2
A8: 6 | B8: =VLOOKUP(D8,Ngan_hang_cau_hoi!$B$2:$K$142,10,0) -> Chương 1 | C8: =VLOOKUP(D8,Ngan_hang_cau_hoi!$B$2:$K$142,9,0) -> Dễ | D8: =INT(A8/5)+1 -> 2 | F8: =IF(L8=2,COUNTIF($L$1:L8,2),"") | G8: =VLOOKUP(D8,Ngan_hang_cau_hoi!$B$2:$K$142,L8,0) -> Case | H8: =IFERROR(VLOOKUP(J8,Ngan_hang_cau_hoi!$I$2:$L$142,4,0),"") | J8: =IF(VLOOKUP(D8,Ngan_hang_cau_hoi!$B$2:$K$142,8,0)=G8,G8,"") | L8: =IF(L7=6,2,L7+1) -> 3
A9: 7 | B9: =VLOOKUP(D9,Ngan_hang_cau_hoi!$B$2:$K$142,10,0) -> Chương 1 | C9: =VLOOKUP(D9,Ngan_hang_cau_hoi!$B$2:$K$142,9,0) -> Dễ | D9: =INT(A9/5)+1 -> 2 | F9: =IF(L9=2,COUNTIF($L$1:L9,2),"") | G9: =VLOOKUP(D9,Ngan_hang_cau_hoi!$B$2:$K$142,L9,0) -> Heatsink/Fan | H9: =IFERROR(VLOOKUP(J9,Ngan_hang_cau_hoi!$I$2:$L$142,4,0),"") -> B | J9: =IF(VLOOKUP(D9,Ngan_hang_cau_hoi!$B$2:$K$142,8,0)=G9,G9,"") -> Heatsink/Fan | L9: =IF(L8=6,2,L8+1) -> 4
A10: 8 | B10: =VLOOKUP(D10,Ngan_hang_cau_hoi!$B$2:$K$142,10,0) -> Chương 1 | C10: =VLOOKUP(D10,Ngan_hang_cau_hoi!$B$2:$K$142,9,0) -> Dễ | D10: =INT(A10/5)+1 -> 2 | F10: =IF(L10=2,COUNTIF($L$1:L10,2),"") | G10: =VLOOKUP(D10,Ngan_hang_cau_hoi!$B$2:$K$142,L10,0) -> RAM | H10: =IFERROR(VLOOKUP(J10,Ngan_hang_cau_hoi!$I$2:$L$142,4,0),"") | J10: =IF(VLOOKUP(D10,Ngan_hang_cau_hoi!$B$2:$K$142,8,0)=G10,G10,"") | L10: =IF(L9=6,2,L9+1) -> 5
A11: 9 | B11: =VLOOKUP(D11,Ngan_hang_cau_hoi!$B$2:$K$142,10,0) -> Chương 1 | C11: =VLOOKUP(D11,Ngan_hang_cau_hoi!$B$2:$K$142,9,0) -> Dễ | D11: =INT(A11/5)+1 -> 2 | F11: =IF(L11=2,COUNTIF($L$1:L11,2),"") | G11: =VLOOKUP(D11,Ngan_hang_cau_hoi!$B$2:$K$142,L11,0) -> SSD | H11: =IFERROR(VLOOKUP(J11,Ngan_hang_cau_hoi!$I$2:$L$142,4,0),"") | J11: =IF(VLOOKUP(D11,Ngan_hang_cau_hoi!$B$2:$K$142,8,0)=G11,G11,"") | L11: =IF(L10=6,2,L10+1) -> 6
A12: 10 | B12: =VLOOKUP(D12,Ngan_hang_cau_hoi!$B$2:$K$142,10,0) -> Chương 1 | C12: =VLOOKUP(D12,Ngan_hang_cau_hoi!$B$2:$K$142,9,0) -> Dễ | D12: =INT(A12/5)+1 -> 3 | F12: =IF(L12=2,COUNTIF($L$1:L12,2),"") -> 3 | G12: =VLOOKUP(D12,Ngan_hang_cau_hoi!$B$2:$K$142,L12,0) -> RAM DDR4 thường có bao nhiêu chân? | H12: =IFERROR(VLOOKUP(J12,Ngan_hang_cau_hoi!$I$2:$L$142,4,0),"") | J12: =IF(VLOOKUP(D12,Ngan_hang_cau_hoi!$B$2:$K$142,8,0)=G12,G12,"") | L12: =IF(L11=6,2,L11+1) -> 2
A13: 11 | B13: =VLOOKUP(D13,Ngan_hang_cau_hoi!$B$2:$K$142,10,0) -> Chương 1 | C13: =VLOOKUP(D13,Ngan_hang_cau_hoi!$B$2:$K$142,9,0) -> Dễ | D13: =INT(A13/5)+1 -> 3 | F13: =IF(L13=2,COUNTIF($L$1:L13,2),"") | G13: =VLOOKUP(D13,Ngan_hang_cau_hoi!$B$2:$K$142,L13,0) -> 240 | H13: =IFERROR(VLOOKUP(J13,Ngan_hang_cau_hoi!$I$2:$L$142,4,0),"") | J13: =IF(VLOOKUP(D13,Ngan_hang_cau_hoi!$B$2:$K$142,8,0)=G13,G13,"") | L13: =IF(L12=6,2,L12+1) -> 3
... A181: 179 | B181: =VLOOKUP(D181,Ngan_hang_cau_hoi!$B$2:$K$142,10,0) -> Chương 1 | C181: =VLOOKUP(D181,Ngan_hang_cau_hoi!$B$2:$K$142,9,0) -> Trung bình | D181: =INT(A181/5)+1 -> 36 | F181: =IF(L181=2,COUNTIF($L$1:L181,2),"") | G181: =VLOOKUP(D181,Ngan_hang_cau_hoi!$B$2:$K$142,L181,0) -> M.2 | H181: =IFERROR(VLOOKUP(J181,Ngan_hang_cau_hoi!$I$2:$L$142,4,0),"") | J181: =IF(VLOOKUP(D181,Ngan_hang_cau_hoi!$B$2:$K$142,8,0)=G181,G181,"") | L181: =IF(L180=6,2,L180+1) -> 6
A182: 180 | B182: =VLOOKUP(D182,Ngan_hang_cau_hoi!$B$2:$K$142,10,0) -> Chương 2 | C182: =VLOOKUP(D182,Ngan_hang_cau_hoi!$B$2:$K$142,9,0) -> Dễ | D182: =INT(A182/5)+1 -> 37 | F182: =IF(L182=2,COUNTIFS($L$1:L182,2,$B$1:B182,"Chương 2"),"") -> 1 | G182: =VLOOKUP(D182,Ngan_hang_cau_hoi!$B$2:$K$142,L182,0) -> Thông số Socket CPU dùng để: | H182: =IFERROR(VLOOKUP(J182,Ngan_hang_cau_hoi!$I$2:$L$142,4,0),"") | J182: =IF(VLOOKUP(D182,Ngan_hang_cau_hoi!$B$2:$K$142,8,0)=G182,G182,"") | L182: =IF(L181=6,2,L181+1) -> 2
A183: 181 | B183: =VLOOKUP(D183,Ngan_hang_cau_hoi!$B$2:$K$142,10,0) -> Chương 2 | C183: =VLOOKUP(D183,Ngan_hang_cau_hoi!$B$2:$K$142,9,0) -> Dễ | D183: =INT(A183/5)+1 -> 37 | F183: =IF(L183=2,COUNTIFS($L$1:L183,2,$B$1:B183,"Chương 2"),"") | G183: =VLOOKUP(D183,Ngan_hang_cau_hoi!$B$2:$K$142,L183,0) -> xác định loại bo mạch chủ tương thích | H183: =IFERROR(VLOOKUP(J183,Ngan_hang_cau_hoi!$I$2:$L$142,4,0),"") -> A | J183: =IF(VLOOKUP(D183,Ngan_hang_cau_hoi!$B$2:$K$142,8,0)=G183,G183,"") -> xác định loại bo mạch chủ tương thích | L183: =IF(L182=6,2,L182+1) -> 3
A184: 182 | B184: =VLOOKUP(D184,Ngan_hang_cau_hoi!$B$2:$K$142,10,0) -> Chương 2 | C184: =VLOOKUP(D184,Ngan_hang_cau_hoi!$B$2:$K$142,9,0) -> Dễ | D184: =INT(A184/5)+1 -> 37 | F184: =IF(L184=2,COUNTIFS($L$1:L184,2,$B$1:B184,"Chương 2"),"") | G184: =VLOOKUP(D184,Ngan_hang_cau_hoi!$B$2:$K$142,L184,0) -> xác định loại RAM | H184: =IFERROR(VLOOKUP(J184,Ngan_hang_cau_hoi!$I$2:$L$142,4,0),"") | J184: =IF(VLOOKUP(D184,Ngan_hang_cau_hoi!$B$2:$K$142,8,0)=G184,G184,"") | L184: =IF(L183=6,2,L183+1) -> 4
A185: 183 | B185: =VLOOKUP(D185,Ngan_hang_cau_hoi!$B$2:$K$142,10,0) -> Chương 2 | C185: =VLOOKUP(D185,Ngan_hang_cau_hoi!$B$2:$K$142,9,0) -> Dễ | D185: =INT(A185/5)+1 -> 37 | F185: =IF(L185=2,COUNTIFS($L$1:L185,2,$B$1:B185,"Chương 2"),"") | G185: =VLOOKUP(D185,Ngan_hang_cau_hoi!$B$2:$K$142,L185,0) -> xác định dung lượng ổ cứng | H185: =IFERROR(VLOOKUP(J185,Ngan_hang_cau_hoi!$I$2:$L$142,4,0),"") | J185: =IF(VLOOKUP(D185,Ngan_hang_cau_hoi!$B$2:$K$142,8,0)=G185,G185,"") | L185: =IF(L184=6,2,L184+1) -> 5
A186: 184 | B186: =VLOOKUP(D186,Ngan_hang_cau_hoi!$B$2:$K$142,10,0) -> Chương 2 | C186: =VLOOKUP(D186,Ngan_hang_cau_hoi!$B$2:$K$142,9,0) -> Dễ | D186: =INT(A186/5)+1 -> 37 | F186: =IF(L186=2,COUNTIFS($L$1:L186,2,$B$1:B186,"Chương 2"),"") | G186: =VLOOKUP(D186,Ngan_hang_cau_hoi!$B$2:$K$142,L186,0) -> xác định card màn hình | H186: =IFERROR(VLOOKUP(J186,Ngan_hang_cau_hoi!$I$2:$L$142,4,0),"") | J186: =IF(VLOOKUP(D186,Ngan_hang_cau_hoi!$B$2:$K$142,8,0)=G186,G186,"") | L186: =IF(L185=6,2,L185+1) -> 6
A187: 185 | B187: =VLOOKUP(D187,Ngan_hang_cau_hoi!$B$2:$K$142,10,0) -> Chương 2 | C187: =VLOOKUP(D187,Ngan_hang_cau_hoi!$B$2:$K$142,9,0) -> Dễ | D187: =INT(A187/5)+1 -> 38 | F187: =IF(L187=2,COUNTIFS($L$1:L187,2,$B$1:B187,"Chương 2"),"") -> 2 | G187: =VLOOKUP(D187,Ngan_hang_cau_hoi!$B$2:$K$142,L187,0) -> Khe PCIe x16 thường dùng để lắp thiết bị nào? | H187: =IFERROR(VLOOKUP(J187,Ngan_hang_cau_hoi!$I$2:$L$142,4,0),"") | J187: =IF(VLOOKUP(D187,Ngan_hang_cau_hoi!$B$2:$K$142,8,0)=G187,G187,"") | L187: =IF(L186=6,2,L186+1) -> 2
A188: 186 | B188: =VLOOKUP(D188,Ngan_hang_cau_hoi!$B$2:$K$142,10,0) -> Chương 2 | C188: =VLOOKUP(D188,Ngan_hang_cau_hoi!$B$2:$K$142,9,0) -> Dễ | D188: =INT(A188/5)+1 -> 38 | F188: =IF(L188=2,COUNTIFS($L$1:L188,2,$B$1:B188,"Chương 2"),"") | G188: =VLOOKUP(D188,Ngan_hang_cau_hoi!$B$2:$K$142,L188,0) -> RAM | H188: =IFERROR(VLOOKUP(J188,Ngan_hang_cau_hoi!$I$2:$L$142,4,0),"") | J188: =IF(VLOOKUP(D188,Ngan_hang_cau_hoi!$B$2:$K$142,8,0)=G188,G188,"") | L188: =IF(L187=6,2,L187+1) -> 3
A189: 187 | B189: =VLOOKUP(D189,Ngan_hang_cau_hoi!$B$2:$K$142,10,0) -> Chương 2 | C189: =VLOOKUP(D189,Ngan_hang_cau_hoi!$B$2:$K$142,9,0) -> Dễ | D189: =INT(A189/5)+1 -> 38 | F189: =IF(L189=2,COUNTIFS($L$1:L189,2,$B$1:B189,"Chương 2"),"") | G189: =VLOOKUP(D189,Ngan_hang_cau_hoi!$B$2:$K$142,L189,0) -> GPU | H189: =IFERROR(VLOOKUP(J189,Ngan_hang_cau_hoi!$I$2:$L$142,4,0),"") -> B | J189: =IF(VLOOKUP(D189,Ngan_hang_cau_hoi!$B$2:$K$142,8,0)=G189,G189,"") -> GPU | L189: =IF(L188=6,2,L188+1) -> 4
A190: 188 | B190: =VLOOKUP(D190,Ngan_hang_cau_hoi!$B$2:$K$142,10,0) -> Chương 2 | C190: =VLOOKUP(D190,Ngan_hang_cau_hoi!$B$2:$K$142,9,0) -> Dễ | D190: =INT(A190/5)+1 -> 38 | F190: =IF(L190=2,COUNTIFS($L$1:L190,2,$B$1:B190,"Chương 2"),"") | G190: =VLOOKUP(D190,Ngan_hang_cau_hoi!$B$2:$K$142,L190,0) -> SSD | H190: =IFERROR(VLOOKUP(J190,Ngan_hang_cau_hoi!$I$2:$L$142,4,0),"") | J190: =IF(VLOOKUP(D190,Ngan_hang_cau_hoi!$B$2:$K$142,8,0)=G190,G190,"") | L190: =IF(L189=6,2,L189+1) -> 5
A191: 189 | B191: =VLOOKUP(D191,Ngan_hang_cau_hoi!$B$2:$K$142,10,0) -> Chương 2 | C191: =VLOOKUP(D191,Ngan_hang_cau_hoi!$B$2:$K$142,9,0) -> Dễ | D191: =INT(A191/5)+1 -> 38 | F191: =IF(L191=2,COUNTIFS($L$1:L191,2,$B$1:B191,"Chương 2"),"") | G191: =VLOOKUP(D191,Ngan_hang_cau_hoi!$B$2:$K$142,L191,0) -> CPU | H191: =IFERROR(VLOOKUP(J191,Ngan_hang_cau_hoi!$I$2:$L$142,4,0),"") | J191: =IF(VLOOKUP(D191,Ngan_hang_cau_hoi!$B$2:$K$142,8,0)=G191,G191,"") | L191: =IF(L190=6,2,L190+1) -> 6
A192: 190 | B192: =VLOOKUP(D192,Ngan_hang_cau_hoi!$B$2:$K$142,10,0) -> Chương 2 | C192: =VLOOKUP(D192,Ngan_hang_cau_hoi!$B$2:$K$142,9,0) -> Dễ | D192: =INT(A192/5)+1 -> 39 | F192: =IF(L192=2,COUNTIFS($L$1:L192,2,$B$1:B192,"Chương 2"),"") -> 3 | G192: =VLOOKUP(D192,Ngan_hang_cau_hoi!$B$2:$K$142,L192,0) -> CPU được lắp vào đâu trên mainboard? | H192: =IFERROR(VLOOKUP(J192,Ngan_hang_cau_hoi!$I$2:$L$142,4,0),"") | J192: =IF(VLOOKUP(D192,Ngan_hang_cau_hoi!$B$2:$K$142,8,0)=G192,G192,"") | L192: =IF(L191=6,2,L191+1) -> 2
A193: 191 | B193: =VLOOKUP(D193,Ngan_hang_cau_hoi!$B$2:$K$142,10,0) -> Chương 2 | C193: =VLOOKUP(D193,Ngan_hang_cau_hoi!$B$2:$K$142,9,0) -> Dễ | D193: =INT(A193/5)+1 -> 39 | F193: =IF(L193=2,COUNTIFS($L$1:L193,2,$B$1:B193,"Chương 2"),"") | G193: =VLOOKUP(D193,Ngan_hang_cau_hoi!$B$2:$K$142,L193,0) -> PCIe slot | H193: =IFERROR(VLOOKUP(J193,Ngan_hang_cau_hoi!$I$2:$L$142,4,0),"") | J193: =IF(VLOOKUP(D193,Ngan_hang_cau_hoi!$B$2:$K$142,8,0)=G193,G193,"") | L193: =IF(L192=6,2,L192+1) -> 3
... A236: 234 | B236: =VLOOKUP(D236,Ngan_hang_cau_hoi!$B$2:$K$142,10,0) -> Chương 2 | C236: =VLOOKUP(D236,Ngan_hang_cau_hoi!$B$2:$K$142,9,0) -> Trung bình | D236: =INT(A236/5)+1 -> 47 | F236: =IF(L236=2,COUNTIFS($L$1:L236,2,$B$1:B236,"Chương 2"),"") | G236: =VLOOKUP(D236,Ngan_hang_cau_hoi!$B$2:$K$142,L236,0) -> Thiếu chuột | H236: =IFERROR(VLOOKUP(J236,Ngan_hang_cau_hoi!$I$2:$L$142,4,0),"") | J236: =IF(VLOOKUP(D236,Ngan_hang_cau_hoi!$B$2:$K$142,8,0)=G236,G236,"") | L236: =IF(L235=6,2,L235+1) -> 6
A237: 235 | B237: =VLOOKUP(D237,Ngan_hang_cau_hoi!$B$2:$K$142,10,0) -> Chương 3 & 4 | C237: =VLOOKUP(D237,Ngan_hang_cau_hoi!$B$2:$K$142,9,0) -> Trung bình | D237: =INT(A237/5)+1 -> 48 | F237: =IF(L237=2,COUNTIFS($L$1:L237,2,$B$1:B237,"Chương 3 & 4"),"") -> 1 | G237: =VLOOKUP(D237,Ngan_hang_cau_hoi!$B$2:$K$142,L237,0) -> Trong quá trình tạo USB boot, thao tác “Start” trong Rufus có nghĩa là: | H237: =IFERROR(VLOOKUP(J237,Ngan_hang_cau_hoi!$I$2:$L$142,4,0),"") | J237: =IF(VLOOKUP(D237,Ngan_hang_cau_hoi!$B$2:$K$142,8,0)=G237,G237,"") | L237: =IF(L236=6,2,L236+1) -> 2
A238: 236 | B238: =VLOOKUP(D238,Ngan_hang_cau_hoi!$B$2:$K$142,10,0) -> Chương 3 & 4 | C238: =VLOOKUP(D238,Ngan_hang_cau_hoi!$B$2:$K$142,9,0) -> Trung bình | D238: =INT(A238/5)+1 -> 48 | F238: =IF(L238=2,COUNTIFS($L$1:L238,2,$B$1:B238,"Chương 3 & 4"),"") | G238: =VLOOKUP(D238,Ngan_hang_cau_hoi!$B$2:$K$142,L238,0) -> Bắt đầu xóa Windows | H238: =IFERROR(VLOOKUP(J238,Ngan_hang_cau_hoi!$I$2:$L$142,4,0),"") | J238: =IF(VLOOKUP(D238,Ngan_hang_cau_hoi!$B$2:$K$142,8,0)=G238,G238,"") | L238: =IF(L237=6,2,L237+1) -> 3
A239: 237 | B239: =VLOOKUP(D239,Ngan_hang_cau_hoi!$B$2:$K$142,10,0) -> Chương 3 & 4 | C239: =VLOOKUP(D239,Ngan_hang_cau_hoi!$B$2:$K$142,9,0) -> Trung bình | D239: =INT(A239/5)+1 -> 48 | F239: =IF(L239=2,COUNTIFS($L$1:L239,2,$B$1:B239,"Chương 3 & 4"),"") | G239: =VLOOKUP(D239,Ngan_hang_cau_hoi!$B$2:$K$142,L239,0) -> Bắt đầu xóa dữ liệu ổ cứng | H239: =IFERROR(VLOOKUP(J239,Ngan_hang_cau_hoi!$I$2:$L$142,4,0),"") | J239: =IF(VLOOKUP(D239,Ngan_hang_cau_hoi!$B$2:$K$142,8,0)=G239,G239,"") | L239: =IF(L238=6,2,L238+1) -> 4
A240: 238 | B240: =VLOOKUP(D240,Ngan_hang_cau_hoi!$B$2:$K$142,10,0) -> Chương 3 & 4 | C240: =VLOOKUP(D240,Ngan_hang_cau_hoi!$B$2:$K$142,9,0) -> Trung bình | D240: =INT(A240/5)+1 -> 48 | F240: =IF(L240=2,COUNTIFS($L$1:L240,2,$B$1:B240,"Chương 3 & 4"),"") | G240: =VLOOKUP(D240,Ngan_hang_cau_hoi!$B$2:$K$142,L240,0) -> Bắt đầu ghi file ISO vào USB | H240: =IFERROR(VLOOKUP(J240,Ngan_hang_cau_hoi!$I$2:$L$142,4,0),"") -> C | J240: =IF(VLOOKUP(D240,Ngan_hang_cau_hoi!$B$2:$K$142,8,0)=G240,G240,"") -> Bắt đầu ghi file ISO vào USB | L240: =IF(L239=6,2,L239+1) -> 5
A241: 239 | B241: =VLOOKUP(D241,Ngan_hang_cau_hoi!$B$2:$K$142,10,0) -> Chương 3 & 4 | C241: =VLOOKUP(D241,Ngan_hang_cau_hoi!$B$2:$K$142,9,0) -> Trung bình | D241: =INT(A241/5)+1 -> 48 | F241: =IF(L241=2,COUNTIFS($L$1:L241,2,$B$1:B241,"Chương 3 & 4"),"") | G241: =VLOOKUP(D241,Ngan_hang_cau_hoi!$B$2:$K$142,L241,0) -> Tăng tốc USB | H241: =IFERROR(VLOOKUP(J241,Ngan_hang_cau_hoi!$I$2:$L$142,4,0),"") | J241: =IF(VLOOKUP(D241,Ngan_hang_cau_hoi!$B$2:$K$142,8,0)=G241,G241,"") | L241: =IF(L240=6,2,L240+1) -> 6
A242: 240 | B242: =VLOOKUP(D242,Ngan_hang_cau_hoi!$B$2:$K$142,10,0) -> Chương 3 & 4 | C242: =VLOOKUP(D242,Ngan_hang_cau_hoi!$B$2:$K$142,9,0) -> Trung bình | D242: =INT(A242/5)+1 -> 49 | F242: =IF(L242=2,COUNTIFS($L$1:L242,2,$B$1:B242,"Chương 3 & 4"),"") -> 2 | G242: =VLOOKUP(D242,Ngan_hang_cau_hoi!$B$2:$K$142,L242,0) -> Trong Norton Ghost, để sao lưu toàn bộ ổ đĩa, chọn: | H242: =IFERROR(VLOOKUP(J242,Ngan_hang_cau_hoi!$I$2:$L$142,4,0),"") | J242: =IF(VLOOKUP(D242,Ngan_hang_cau_hoi!$B$2:$K$142,8,0)=G242,G242,"") | L242: =IF(L241=6,2,L241+1) -> 2
A243: 241 | B243: =VLOOKUP(D243,Ngan_hang_cau_hoi!$B$2:$K$142,10,0) -> Chương 3 & 4 | C243: =VLOOKUP(D243,Ngan_hang_cau_hoi!$B$2:$K$142,9,0) -> Trung bình | D243: =INT(A243/5)+1 -> 49 | F243: =IF(L243=2,COUNTIFS($L$1:L243,2,$B$1:B243,"Chương 3 & 4"),"") | G243: =VLOOKUP(D243,Ngan_hang_cau_hoi!$B$2:$K$142,L243,0) -> Partition to Image | H243: =IFERROR(VLOOKUP(J243,Ngan_hang_cau_hoi!$I$2:$L$142,4,0),"") | J243: =IF(VLOOKUP(D243,Ngan_hang_cau_hoi!$B$2:$K$142,8,0)=G243,G243,"") | L243: =IF(L242=6,2,L242+1) -> 3
A244: 242 | B244: =VLOOKUP(D244,Ngan_hang_cau_hoi!$B$2:$K$142,10,0) -> Chương 3 & 4 | C244: =VLOOKUP(D244,Ngan_hang_cau_hoi!$B$2:$K$142,9,0) -> Trung bình | D244: =INT(A244/5)+1 -> 49 | F244: =IF(L244=2,COUNTIFS($L$1:L244,2,$B$1:B244,"Chương 3 & 4"),"") | G244: =VLOOKUP(D244,Ngan_hang_cau_hoi!$B$2:$K$142,L244,0) -> Image to Disk | H244: =IFERROR(VLOOKUP(J244,Ngan_hang_cau_hoi!$I$2:$L$142,4,0),"") | J244: =IF(VLOOKUP(D244,Ngan_hang_cau_hoi!$B$2:$K$142,8,0)=G244,G244,"") | L244: =IF(L243=6,2,L243+1) -> 4
A245: 243 | B245: =VLOOKUP(D245,Ngan_hang_cau_hoi!$B$2:$K$142,10,0) -> Chương 3 & 4 | C245: =VLOOKUP(D245,Ngan_hang_cau_hoi!$B$2:$K$142,9,0) -> Trung bình | D245: =INT(A245/5)+1 -> 49 | F245: =IF(L245=2,COUNTIFS($L$1:L245,2,$B$1:B245,"Chương 3 & 4"),"") | G245: =VLOOKUP(D245,Ngan_hang_cau_hoi!$B$2:$K$142,L245,0) -> Disk to Partition | H245: =IFERROR(VLOOKUP(J245,Ngan_hang_cau_hoi!$I$2:$L$142,4,0),"") | J245: =IF(VLOOKUP(D245,Ngan_hang_cau_hoi!$B$2:$K$142,8,0)=G245,G245,"") | L245: =IF(L244=6,2,L244+1) -> 5
A246: 244 | B246: =VLOOKUP(D246,Ngan_hang_cau_hoi!$B$2:$K$142,10,0) -> Chương 3 & 4 | C246: =VLOOKUP(D246,Ngan_hang_cau_hoi!$B$2:$K$142,9,0) -> Trung bình | D246: =INT(A246/5)+1 -> 49 | F246: =IF(L246=2,COUNTIFS($L$1:L246,2,$B$1:B246,"Chương 3 & 4"),"") | G246: =VLOOKUP(D246,Ngan_hang_cau_hoi!$B$2:$K$142,L246,0) -> Disk to Image | H246: =IFERROR(VLOOKUP(J246,Ngan_hang_cau_hoi!$I$2:$L$142,4,0),"") -> D | J246: =IF(VLOOKUP(D246,Ngan_hang_cau_hoi!$B$2:$K$142,8,0)=G246,G246,"") -> Disk to Image | L246: =IF(L245=6,2,L245+1) -> 6
A247: 245 | B247: =VLOOKUP(D247,Ngan_hang_cau_hoi!$B$2:$K$142,10,0) -> Chương 3 & 4 | C247: =VLOOKUP(D247,Ngan_hang_cau_hoi!$B$2:$K$142,9,0) -> Trung bình | D247: =INT(A247/5)+1 -> 50 | F247: =IF(L247=2,COUNTIFS($L$1:L247,2,$B$1:B247,"Chương 3 & 4"),"") -> 3 | G247: =VLOOKUP(D247,Ngan_hang_cau_hoi!$B$2:$K$142,L247,0) -> Trong Hệ điều hành Windows, công cụ nào dùng để tạo bản sao toàn bộ hệ thống? | H247: =IFERROR(VLOOKUP(J247,Ngan_hang_cau_hoi!$I$2:$L$142,4,0),"") | J247: =IF(VLOOKUP(D247,Ngan_hang_cau_hoi!$B$2:$K$142,8,0)=G247,G247,"") | L247: =IF(L246=6,2,L246+1) -> 2
A248: 246 | B248: =VLOOKUP(D248,Ngan_hang_cau_hoi!$B$2:$K$142,10,0) -> Chương 3 & 4 | C248: =VLOOKUP(D248,Ngan_hang_cau_hoi!$B$2:$K$142,9,0) -> Trung bình | D248: =INT(A248/5)+1 -> 50 | F248: =IF(L248=2,COUNTIFS($L$1:L248,2,$B$1:B248,"Chương 3 & 4"),"") | G248: =VLOOKUP(D248,Ngan_hang_cau_hoi!$B$2:$K$142,L248,0) -> Disk Cleanup | H248: =IFERROR(VLOOKUP(J248,Ngan_hang_cau_hoi!$I$2:$L$142,4,0),"") | J248: =IF(VLOOKUP(D248,Ngan_hang_cau_hoi!$B$2:$K$142,8,0)=G248,G248,"") | L248: =IF(L247=6,2,L247+1) -> 3
... A381: 379 | B381: =VLOOKUP(D381,Ngan_hang_cau_hoi!$B$2:$K$142,10,0) -> Chương 3 & 4 | C381: =VLOOKUP(D381,Ngan_hang_cau_hoi!$B$2:$K$142,9,0) -> Trung bình | D381: =INT(A381/5)+1 -> 76 | F381: =IF(L381=2,COUNTIFS($L$1:L381,2,$B$1:B381,"Chương 3 & 4"),"") | G381: =VLOOKUP(D381,Ngan_hang_cau_hoi!$B$2:$K$142,L381,0) -> Không hỗ trợ hệ điều hành | H381: =IFERROR(VLOOKUP(J381,Ngan_hang_cau_hoi!$I$2:$L$142,4,0),"") | J381: =IF(VLOOKUP(D381,Ngan_hang_cau_hoi!$B$2:$K$142,8,0)=G381,G381,"") | L381: =IF(L380=6,2,L380+1) -> 6
...

Sheet CLC
A1: Chương | B1: LV | C1: TT | D1: Nội dung câu hỏi | E1: Đáp án | F1: Thang điểm
D2: Chương 1
D3: Nhóm câu hỏi ở mức độ NHẬN BIẾT/ THÔNG HIỂU (A)
A4: Chương 1 | B4: Dễ | C4: 1 | D4: Tốc độ đọc/ghi dữ liệu giữu ổ cứng SSD và HDD | F4: 0.2
A5: Chương 1 | B5: Dễ | D5: Tốc độ đọc/ghi dữ liệu của ổ cứng bằng nhau.
A6: Chương 1 | B6: Dễ | D6: Tốc độ đọc/ghi dữ liệu của ổ cứng HDD nhanh hơn.
A7: Chương 1 | B7: Dễ | D7: Tốc độ đọc/ghi dữ liệu của ổ cứng SSD nhanh hơn. | E7: C
A8: Chương 1 | B8: Dễ | D8: Tốc độ đọc/ghi dữ liệu của ổ cứng SSD chậm hơn.
A9: Chương 1 | B9: Dễ | C9: 2 | D9: Thiết bị nào giúp làm mát CPU? | F9: 0.2
A10: Chương 1 | B10: Dễ | D10: Case
A11: Chương 1 | B11: Dễ | D11: Heatsink/Fan | E11: B
A12: Chương 1 | B12: Dễ | D12: RAM
A13: Chương 1 | B13: Dễ | D13: SSD
A14: Chương 1 | B14: Dễ | C14: 3 | D14: RAM DDR4 thường có bao nhiêu chân? | F14: 0.2
A15: Chương 1 | B15: Dễ | D15: 240
A16: Chương 1 | B16: Dễ | D16: 288 | E16: B
A17: Chương 1 | B17: Dễ | D17: 184
A18: Chương 1 | B18: Dễ | D18: 200
A19: Chương 1 | B19: Dễ | C19: 4 | D19: RAM có chức năng chính là gì? | F19: 0.2
A20: Chương 1 | B20: Dễ | D20: Lưu trữ tạm thời | E20: A
A21: Chương 1 | B21: Dễ | D21: Lưu trữ lâu dài
A22: Chương 1 | B22: Dễ | D22: Xuất hình ảnh
A23: Chương 1 | B23: Dễ | D23: Cấp điện
A24: Chương 1 | B24: Dễ | C24: 5 | D24: Ổ SSD SATA thường có kích thước phổ biến nào? | F24: 0.2
A25: Chương 1 | B25: Dễ | D25: 3.5 inch
A26: Chương 1 | B26: Dễ | D26: 2.5 inch | E26: B
A27: Chương 1 | B27: Dễ | D27: 5 inch
A28: Chương 1 | B28: Dễ | D28: 1.8 inch
A29: Chương 1 | B29: Dễ | C29: 6 | D29: Ổ SSD SATA cần nguồn từ: | F29: 0.2
A30: Chương 1 | B30: Dễ | D30: Cáp PCI-E
A31: Chương 1 | B31: Dễ | D31: Cáp SATA power | E31: B
A32: Chương 1 | B32: Dễ | D32: Cáp VGA
A33: Chương 1 | B33: Dễ | D33: Cáp USB
A34: Chương 1 | B34: Dễ | C34: 7 | D34: Ổ cứng SSD lưu dữ liệu bằng công nghệ nào? | F34: 0.2
A35: Chương 1 | B35: Dễ | D35: ổ SSD sử công nghệ lưu trữ từ tính.
A36: Chương 1 | B36: Dễ | D36: ổ SSD sử công nghệ lưu trữ flash. | E36: B
A37: Chương 1 | B37: Dễ | D37: ổ SSD sử công nghệ lưu trữ đĩa từ và đầu kim đọc dữ liệu
A38: Chương 1 | B38: Dễ | D38: ổ SSD chỉ để đọc dữ liệu. Dữ liệu được ghi vào từ lúc sản xuất.
A39: Chương 1 | B39: Dễ | C39: 8 | D39: Nguồn máy tính còn gọi là gì? | F39: 0.2
A40: Chương 1 | B40: Dễ | D40: GPU
...

Sheet thường
A1: Chương | B1: LV | C1: TT | D1: Nội dung câu hỏi | E1: Đáp án | F1: Thang điểm
D2: Chương 1
D3: Nhóm câu hỏi ở mức độ NHẬN BIẾT/ THÔNG HIỂU (A)
A4: Chương 1 | B4: Dễ | C4: 1 | D4: CPU có cache L1, L2, L3. Trong đó cache nhanh nhất là: | F4: 0.2
A5: Chương 1 | B5: Dễ | D5: L1 | E5: A
A6: Chương 1 | B6: Dễ | D6: L2
A7: Chương 1 | B7: Dễ | D7: L3
A8: Chương 1 | B8: Dễ | D8: Như nhau, chỉ khác về dung lượng
A9: Chương 1 | B9: Dễ | C9: 2 | D9: Mainboard là gì? | F9: 0.2
A10: Chương 1 | B10: Dễ | D10: Thiết bị lưu trữ
A11: Chương 1 | B11: Dễ | D11: Bo mạch chủ | E11: B
A12: Chương 1 | B12: Dễ | D12: Thiết bị xuất hình
A13: Chương 1 | B13: Dễ | D13: Thiết bị nhập
A14: Chương 1 | B14: Dễ | C14: 3 | D14: Mainboard Micro-ATX có thể lắp vào case ATX không? | F14: 0.2
A15: Chương 1 | B15: Dễ | D15: Có | E15: A
A16: Chương 1 | B16: Dễ | D16: Không
A17: Chương 1 | B17: Dễ | D17: Chỉ khi dùng adapter
A18: Chương 1 | B18: Dễ | D18: Chỉ khi nâng cấp BIOS
A19: Chương 1 | B19: Dễ | C19: 4 | D19: Nếu CPU không đúng socket với mainboard thì: | F19: 0.2
A20: Chương 1 | B20: Dễ | D20: Lắp được nhưng máy chạy chậm.
A21: Chương 1 | B21: Dễ | D21: Không lắp được CPU. | E21: B
A22: Chương 1 | B22: Dễ | D22: Không nhận RAM.
A23: Chương 1 | B23: Dễ | D23: Không có vấn đề gì.
A24: Chương 1 | B24: Dễ | C24: 5 | D24: Nếu mainboard hỗ trợ DDR5, RAM DDR4 sẽ: | F24: 0.2
A25: Chương 1 | B25: Dễ | D25: Chạy chậm
A26: Chương 1 | B26: Dễ | D26: Không lắp được | E26: B
A27: Chương 1 | B27: Dễ | D27: Chạy bình thường
A28: Chương 1 | B28: Dễ | D28: Chạy nửa tốc độ
A29: Chương 1 | B29: Dễ | C29: 6 | D29: Nguồn máy tính còn gọi là gì? | F29: 0.2
A30: Chương 1 | B30: Dễ | D30: GPU
A31: Chương 1 | B31: Dễ | D31: PSU | E31: B
A32: Chương 1 | B32: Dễ | D32: UPS
A33: Chương 1 | B33: Dễ | D33: ROM
A34: Chương 1 | B34: Dễ | C34: 7 | D34: Ổ cứng SSD lưu dữ liệu bằng công nghệ nào? | F34: 0.2
A35: Chương 1 | B35: Dễ | D35: ổ SSD sử công nghệ lưu trữ từ tính.
A36: Chương 1 | B36: Dễ | D36: ổ SSD sử công nghệ lưu trữ flash. | E36: B
A37: Chương 1 | B37: Dễ | D37: ổ SSD sử công nghệ lưu trữ đĩa từ và đầu kim đọc dữ liệu
A38: Chương 1 | B38: Dễ | D38: ổ SSD chỉ để đọc dữ liệu. Dữ liệu được ghi vào từ lúc sản xuất.
A39: Chương 1 | B39: Dễ | C39: 8 | D39: Ổ SSD SATA cần nguồn từ: | F39: 0.2
A40: Chương 1 | B40: Dễ | D40: Cáp PCI-E
...
